2024-07-15 20:16:49,011 -  nornir.core -     INFO -        run() - Running task 'another_show_command_test' with args {} on 4 hosts
2024-07-15 20:44:11,543 -  nornir.core -     INFO -        run() - Running task 'another_show_command_test' with args {} on 4 hosts
2024-07-15 20:53:51,238 -  nornir.core -     INFO -        run() - Running task 'recursive_send_config' with args {} on 4 hosts
2024-07-15 20:54:07,922 -  nornir.core -     INFO -        run() - Running task 'recursive_send_config' with args {} on 4 hosts
2024-07-15 20:54:32,048 -  nornir.core -     INFO -        run() - Running task 'recursive_send_config' with args {} on 4 hosts
2024-07-15 20:54:44,553 -  nornir.core -     INFO -        run() - Running task 'recursive_send_config' with args {} on 4 hosts
2024-07-15 21:25:18,605 -  nornir.core -     INFO -        run() - Running task 'napalm_getters' with args {} on 4 hosts
2024-07-15 21:25:18,610 - nornir.core.task -    ERROR -      start() - Host 'R3': task 'napalm_getters' failed with traceback:
Traceback (most recent call last):
  File "/Users/maiconlucinda/Documents/Python Code/Network Automation Python/nornir/.venv/lib/python3.11/site-packages/nornir/core/task.py", line 99, in start
    r = self.task(self, **self.params)
        ^^^^^^^^^^^^^^^^^^^^^^^^^^^^^^
  File "/Users/maiconlucinda/Documents/Python Code/Network Automation Python/nornir/13_nornir_napalm_getters.py", line 10, in napalm_getters
    task.run(napalm_get, task="show version")
TypeError: Task.run() got multiple values for argument 'task'

2024-07-15 21:25:18,611 - nornir.core.task -    ERROR -      start() - Host 'R2': task 'napalm_getters' failed with traceback:
Traceback (most recent call last):
  File "/Users/maiconlucinda/Documents/Python Code/Network Automation Python/nornir/.venv/lib/python3.11/site-packages/nornir/core/task.py", line 99, in start
    r = self.task(self, **self.params)
        ^^^^^^^^^^^^^^^^^^^^^^^^^^^^^^
  File "/Users/maiconlucinda/Documents/Python Code/Network Automation Python/nornir/13_nornir_napalm_getters.py", line 10, in napalm_getters
    task.run(napalm_get, task="show version")
TypeError: Task.run() got multiple values for argument 'task'

2024-07-15 21:25:18,611 - nornir.core.task -    ERROR -      start() - Host 'R4': task 'napalm_getters' failed with traceback:
Traceback (most recent call last):
  File "/Users/maiconlucinda/Documents/Python Code/Network Automation Python/nornir/.venv/lib/python3.11/site-packages/nornir/core/task.py", line 99, in start
    r = self.task(self, **self.params)
        ^^^^^^^^^^^^^^^^^^^^^^^^^^^^^^
  File "/Users/maiconlucinda/Documents/Python Code/Network Automation Python/nornir/13_nornir_napalm_getters.py", line 10, in napalm_getters
    task.run(napalm_get, task="show version")
TypeError: Task.run() got multiple values for argument 'task'

2024-07-15 21:25:18,611 - nornir.core.task -    ERROR -      start() - Host 'R1': task 'napalm_getters' failed with traceback:
Traceback (most recent call last):
  File "/Users/maiconlucinda/Documents/Python Code/Network Automation Python/nornir/.venv/lib/python3.11/site-packages/nornir/core/task.py", line 99, in start
    r = self.task(self, **self.params)
        ^^^^^^^^^^^^^^^^^^^^^^^^^^^^^^
  File "/Users/maiconlucinda/Documents/Python Code/Network Automation Python/nornir/13_nornir_napalm_getters.py", line 10, in napalm_getters
    task.run(napalm_get, task="show version")
TypeError: Task.run() got multiple values for argument 'task'

2024-07-15 21:25:52,004 -  nornir.core -     INFO -        run() - Running task 'napalm_getters' with args {} on 4 hosts
2024-07-15 21:25:52,007 - nornir.core.task -    ERROR -      start() - Host 'R3': task 'napalm_getters' failed with traceback:
Traceback (most recent call last):
  File "/Users/maiconlucinda/Documents/Python Code/Network Automation Python/nornir/.venv/lib/python3.11/site-packages/nornir/core/task.py", line 99, in start
    r = self.task(self, **self.params)
        ^^^^^^^^^^^^^^^^^^^^^^^^^^^^^^
  File "/Users/maiconlucinda/Documents/Python Code/Network Automation Python/nornir/13_nornir_napalm_getters.py", line 10, in napalm_getters
    task.run(napalm_get, task="show version")
TypeError: Task.run() got multiple values for argument 'task'

2024-07-15 21:25:52,007 - nornir.core.task -    ERROR -      start() - Host 'R4': task 'napalm_getters' failed with traceback:
Traceback (most recent call last):
  File "/Users/maiconlucinda/Documents/Python Code/Network Automation Python/nornir/.venv/lib/python3.11/site-packages/nornir/core/task.py", line 99, in start
    r = self.task(self, **self.params)
        ^^^^^^^^^^^^^^^^^^^^^^^^^^^^^^
  File "/Users/maiconlucinda/Documents/Python Code/Network Automation Python/nornir/13_nornir_napalm_getters.py", line 10, in napalm_getters
    task.run(napalm_get, task="show version")
TypeError: Task.run() got multiple values for argument 'task'

2024-07-15 21:25:52,007 - nornir.core.task -    ERROR -      start() - Host 'R1': task 'napalm_getters' failed with traceback:
Traceback (most recent call last):
  File "/Users/maiconlucinda/Documents/Python Code/Network Automation Python/nornir/.venv/lib/python3.11/site-packages/nornir/core/task.py", line 99, in start
    r = self.task(self, **self.params)
        ^^^^^^^^^^^^^^^^^^^^^^^^^^^^^^
  File "/Users/maiconlucinda/Documents/Python Code/Network Automation Python/nornir/13_nornir_napalm_getters.py", line 10, in napalm_getters
    task.run(napalm_get, task="show version")
TypeError: Task.run() got multiple values for argument 'task'

2024-07-15 21:25:52,008 - nornir.core.task -    ERROR -      start() - Host 'R2': task 'napalm_getters' failed with traceback:
Traceback (most recent call last):
  File "/Users/maiconlucinda/Documents/Python Code/Network Automation Python/nornir/.venv/lib/python3.11/site-packages/nornir/core/task.py", line 99, in start
    r = self.task(self, **self.params)
        ^^^^^^^^^^^^^^^^^^^^^^^^^^^^^^
  File "/Users/maiconlucinda/Documents/Python Code/Network Automation Python/nornir/13_nornir_napalm_getters.py", line 10, in napalm_getters
    task.run(napalm_get, task="show version")
TypeError: Task.run() got multiple values for argument 'task'

2024-07-15 21:26:58,563 -  nornir.core -     INFO -        run() - Running task 'napalm_getters' with args {} on 4 hosts
2024-07-15 21:27:59,477 -  nornir.core -     INFO -        run() - Running task 'napalm_getters' with args {} on 4 hosts
2024-07-15 21:29:35,864 -  nornir.core -     INFO -        run() - Running task 'napalm_getters' with args {} on 4 hosts
2024-07-15 21:36:54,848 -  nornir.core -     INFO -        run() - Running task 'ping_test' with args {} on 4 hosts
2024-07-15 21:37:46,178 -  nornir.core -     INFO -        run() - Running task 'ping_test' with args {} on 4 hosts
2024-07-15 21:37:57,872 - nornir.core.task -    ERROR -      start() - Host 'R1': task 'napalm_ping' failed with traceback:
Traceback (most recent call last):
  File "/Users/maiconlucinda/Documents/Python Code/Network Automation Python/nornir/.venv/lib/python3.11/site-packages/nornir/core/task.py", line 99, in start
    r = self.task(self, **self.params)
        ^^^^^^^^^^^^^^^^^^^^^^^^^^^^^^
  File "/Users/maiconlucinda/Documents/Python Code/Network Automation Python/nornir/.venv/lib/python3.11/site-packages/nornir_napalm/plugins/tasks/napalm_ping.py", line 37, in napalm_ping
    result = device.ping(
             ^^^^^^^^^^^^
  File "/Users/maiconlucinda/Documents/Python Code/Network Automation Python/nornir/.venv/lib/python3.11/site-packages/napalm/ios/ios.py", line 3387, in ping
    output = self._send_command(command)
             ^^^^^^^^^^^^^^^^^^^^^^^^^^^
  File "/Users/maiconlucinda/Documents/Python Code/Network Automation Python/nornir/.venv/lib/python3.11/site-packages/napalm/ios/ios.py", line 209, in _send_command
    output = self.device.send_command(command)
             ^^^^^^^^^^^^^^^^^^^^^^^^^^^^^^^^^
  File "/Users/maiconlucinda/Documents/Python Code/Network Automation Python/nornir/.venv/lib/python3.11/site-packages/netmiko/base_connection.py", line 111, in wrapper_decorator
    return_val = func(self, *args, **kwargs)
                 ^^^^^^^^^^^^^^^^^^^^^^^^^^^
  File "/Users/maiconlucinda/Documents/Python Code/Network Automation Python/nornir/.venv/lib/python3.11/site-packages/netmiko/utilities.py", line 596, in wrapper_decorator
    return func(self, *args, **kwargs)
           ^^^^^^^^^^^^^^^^^^^^^^^^^^^
  File "/Users/maiconlucinda/Documents/Python Code/Network Automation Python/nornir/.venv/lib/python3.11/site-packages/netmiko/base_connection.py", line 1826, in send_command
    raise ReadTimeout(msg)
netmiko.exceptions.ReadTimeout: 
Pattern not detected: 'R1\\#' in output.

Things you might try to fix this:
1. Explicitly set your pattern using the expect_string argument.
2. Increase the read_timeout to a larger value.

You can also look at the Netmiko session_log or debug log for more information.



2024-07-15 21:37:57,873 - nornir.core.task -    ERROR -      start() - Host 'R1': task 'ping_test' failed with traceback:
Traceback (most recent call last):
  File "/Users/maiconlucinda/Documents/Python Code/Network Automation Python/nornir/.venv/lib/python3.11/site-packages/nornir/core/task.py", line 99, in start
    r = self.task(self, **self.params)
        ^^^^^^^^^^^^^^^^^^^^^^^^^^^^^^
  File "/Users/maiconlucinda/Documents/Python Code/Network Automation Python/nornir/14_nornir_napalm_get_ping.py", line 10, in ping_test
    task.run(napalm_ping, dest="200.200.200.200")
  File "/Users/maiconlucinda/Documents/Python Code/Network Automation Python/nornir/.venv/lib/python3.11/site-packages/nornir/core/task.py", line 174, in run
    raise NornirSubTaskError(task=run_task, result=r)
nornir.core.exceptions.NornirSubTaskError: Subtask: napalm_ping (failed)


2024-07-15 21:37:57,969 - nornir.core.task -    ERROR -      start() - Host 'R2': task 'napalm_ping' failed with traceback:
Traceback (most recent call last):
  File "/Users/maiconlucinda/Documents/Python Code/Network Automation Python/nornir/.venv/lib/python3.11/site-packages/nornir/core/task.py", line 99, in start
    r = self.task(self, **self.params)
        ^^^^^^^^^^^^^^^^^^^^^^^^^^^^^^
  File "/Users/maiconlucinda/Documents/Python Code/Network Automation Python/nornir/.venv/lib/python3.11/site-packages/nornir_napalm/plugins/tasks/napalm_ping.py", line 37, in napalm_ping
    result = device.ping(
             ^^^^^^^^^^^^
  File "/Users/maiconlucinda/Documents/Python Code/Network Automation Python/nornir/.venv/lib/python3.11/site-packages/napalm/ios/ios.py", line 3387, in ping
    output = self._send_command(command)
             ^^^^^^^^^^^^^^^^^^^^^^^^^^^
  File "/Users/maiconlucinda/Documents/Python Code/Network Automation Python/nornir/.venv/lib/python3.11/site-packages/napalm/ios/ios.py", line 209, in _send_command
    output = self.device.send_command(command)
             ^^^^^^^^^^^^^^^^^^^^^^^^^^^^^^^^^
  File "/Users/maiconlucinda/Documents/Python Code/Network Automation Python/nornir/.venv/lib/python3.11/site-packages/netmiko/base_connection.py", line 111, in wrapper_decorator
    return_val = func(self, *args, **kwargs)
                 ^^^^^^^^^^^^^^^^^^^^^^^^^^^
  File "/Users/maiconlucinda/Documents/Python Code/Network Automation Python/nornir/.venv/lib/python3.11/site-packages/netmiko/utilities.py", line 596, in wrapper_decorator
    return func(self, *args, **kwargs)
           ^^^^^^^^^^^^^^^^^^^^^^^^^^^
  File "/Users/maiconlucinda/Documents/Python Code/Network Automation Python/nornir/.venv/lib/python3.11/site-packages/netmiko/base_connection.py", line 1826, in send_command
    raise ReadTimeout(msg)
netmiko.exceptions.ReadTimeout: 
Pattern not detected: 'R2\\#' in output.

Things you might try to fix this:
1. Explicitly set your pattern using the expect_string argument.
2. Increase the read_timeout to a larger value.

You can also look at the Netmiko session_log or debug log for more information.



2024-07-15 21:37:57,970 - nornir.core.task -    ERROR -      start() - Host 'R2': task 'ping_test' failed with traceback:
Traceback (most recent call last):
  File "/Users/maiconlucinda/Documents/Python Code/Network Automation Python/nornir/.venv/lib/python3.11/site-packages/nornir/core/task.py", line 99, in start
    r = self.task(self, **self.params)
        ^^^^^^^^^^^^^^^^^^^^^^^^^^^^^^
  File "/Users/maiconlucinda/Documents/Python Code/Network Automation Python/nornir/14_nornir_napalm_get_ping.py", line 10, in ping_test
    task.run(napalm_ping, dest="200.200.200.200")
  File "/Users/maiconlucinda/Documents/Python Code/Network Automation Python/nornir/.venv/lib/python3.11/site-packages/nornir/core/task.py", line 174, in run
    raise NornirSubTaskError(task=run_task, result=r)
nornir.core.exceptions.NornirSubTaskError: Subtask: napalm_ping (failed)


2024-07-15 21:37:57,970 - nornir.core.task -    ERROR -      start() - Host 'R4': task 'napalm_ping' failed with traceback:
Traceback (most recent call last):
  File "/Users/maiconlucinda/Documents/Python Code/Network Automation Python/nornir/.venv/lib/python3.11/site-packages/nornir/core/task.py", line 99, in start
    r = self.task(self, **self.params)
        ^^^^^^^^^^^^^^^^^^^^^^^^^^^^^^
  File "/Users/maiconlucinda/Documents/Python Code/Network Automation Python/nornir/.venv/lib/python3.11/site-packages/nornir_napalm/plugins/tasks/napalm_ping.py", line 37, in napalm_ping
    result = device.ping(
             ^^^^^^^^^^^^
  File "/Users/maiconlucinda/Documents/Python Code/Network Automation Python/nornir/.venv/lib/python3.11/site-packages/napalm/ios/ios.py", line 3387, in ping
    output = self._send_command(command)
             ^^^^^^^^^^^^^^^^^^^^^^^^^^^
  File "/Users/maiconlucinda/Documents/Python Code/Network Automation Python/nornir/.venv/lib/python3.11/site-packages/napalm/ios/ios.py", line 209, in _send_command
    output = self.device.send_command(command)
             ^^^^^^^^^^^^^^^^^^^^^^^^^^^^^^^^^
  File "/Users/maiconlucinda/Documents/Python Code/Network Automation Python/nornir/.venv/lib/python3.11/site-packages/netmiko/base_connection.py", line 111, in wrapper_decorator
    return_val = func(self, *args, **kwargs)
                 ^^^^^^^^^^^^^^^^^^^^^^^^^^^
  File "/Users/maiconlucinda/Documents/Python Code/Network Automation Python/nornir/.venv/lib/python3.11/site-packages/netmiko/utilities.py", line 596, in wrapper_decorator
    return func(self, *args, **kwargs)
           ^^^^^^^^^^^^^^^^^^^^^^^^^^^
  File "/Users/maiconlucinda/Documents/Python Code/Network Automation Python/nornir/.venv/lib/python3.11/site-packages/netmiko/base_connection.py", line 1826, in send_command
    raise ReadTimeout(msg)
netmiko.exceptions.ReadTimeout: 
Pattern not detected: 'R4\\#' in output.

Things you might try to fix this:
1. Explicitly set your pattern using the expect_string argument.
2. Increase the read_timeout to a larger value.

You can also look at the Netmiko session_log or debug log for more information.



2024-07-15 21:37:57,971 - nornir.core.task -    ERROR -      start() - Host 'R4': task 'ping_test' failed with traceback:
Traceback (most recent call last):
  File "/Users/maiconlucinda/Documents/Python Code/Network Automation Python/nornir/.venv/lib/python3.11/site-packages/nornir/core/task.py", line 99, in start
    r = self.task(self, **self.params)
        ^^^^^^^^^^^^^^^^^^^^^^^^^^^^^^
  File "/Users/maiconlucinda/Documents/Python Code/Network Automation Python/nornir/14_nornir_napalm_get_ping.py", line 10, in ping_test
    task.run(napalm_ping, dest="200.200.200.200")
  File "/Users/maiconlucinda/Documents/Python Code/Network Automation Python/nornir/.venv/lib/python3.11/site-packages/nornir/core/task.py", line 174, in run
    raise NornirSubTaskError(task=run_task, result=r)
nornir.core.exceptions.NornirSubTaskError: Subtask: napalm_ping (failed)


2024-07-15 21:37:58,025 - nornir.core.task -    ERROR -      start() - Host 'R3': task 'napalm_ping' failed with traceback:
Traceback (most recent call last):
  File "/Users/maiconlucinda/Documents/Python Code/Network Automation Python/nornir/.venv/lib/python3.11/site-packages/nornir/core/task.py", line 99, in start
    r = self.task(self, **self.params)
        ^^^^^^^^^^^^^^^^^^^^^^^^^^^^^^
  File "/Users/maiconlucinda/Documents/Python Code/Network Automation Python/nornir/.venv/lib/python3.11/site-packages/nornir_napalm/plugins/tasks/napalm_ping.py", line 37, in napalm_ping
    result = device.ping(
             ^^^^^^^^^^^^
  File "/Users/maiconlucinda/Documents/Python Code/Network Automation Python/nornir/.venv/lib/python3.11/site-packages/napalm/ios/ios.py", line 3387, in ping
    output = self._send_command(command)
             ^^^^^^^^^^^^^^^^^^^^^^^^^^^
  File "/Users/maiconlucinda/Documents/Python Code/Network Automation Python/nornir/.venv/lib/python3.11/site-packages/napalm/ios/ios.py", line 209, in _send_command
    output = self.device.send_command(command)
             ^^^^^^^^^^^^^^^^^^^^^^^^^^^^^^^^^
  File "/Users/maiconlucinda/Documents/Python Code/Network Automation Python/nornir/.venv/lib/python3.11/site-packages/netmiko/base_connection.py", line 111, in wrapper_decorator
    return_val = func(self, *args, **kwargs)
                 ^^^^^^^^^^^^^^^^^^^^^^^^^^^
  File "/Users/maiconlucinda/Documents/Python Code/Network Automation Python/nornir/.venv/lib/python3.11/site-packages/netmiko/utilities.py", line 596, in wrapper_decorator
    return func(self, *args, **kwargs)
           ^^^^^^^^^^^^^^^^^^^^^^^^^^^
  File "/Users/maiconlucinda/Documents/Python Code/Network Automation Python/nornir/.venv/lib/python3.11/site-packages/netmiko/base_connection.py", line 1826, in send_command
    raise ReadTimeout(msg)
netmiko.exceptions.ReadTimeout: 
Pattern not detected: 'R3\\#' in output.

Things you might try to fix this:
1. Explicitly set your pattern using the expect_string argument.
2. Increase the read_timeout to a larger value.

You can also look at the Netmiko session_log or debug log for more information.



2024-07-15 21:37:58,025 - nornir.core.task -    ERROR -      start() - Host 'R3': task 'ping_test' failed with traceback:
Traceback (most recent call last):
  File "/Users/maiconlucinda/Documents/Python Code/Network Automation Python/nornir/.venv/lib/python3.11/site-packages/nornir/core/task.py", line 99, in start
    r = self.task(self, **self.params)
        ^^^^^^^^^^^^^^^^^^^^^^^^^^^^^^
  File "/Users/maiconlucinda/Documents/Python Code/Network Automation Python/nornir/14_nornir_napalm_get_ping.py", line 10, in ping_test
    task.run(napalm_ping, dest="200.200.200.200")
  File "/Users/maiconlucinda/Documents/Python Code/Network Automation Python/nornir/.venv/lib/python3.11/site-packages/nornir/core/task.py", line 174, in run
    raise NornirSubTaskError(task=run_task, result=r)
nornir.core.exceptions.NornirSubTaskError: Subtask: napalm_ping (failed)


2024-07-15 21:38:30,365 -  nornir.core -     INFO -        run() - Running task 'ping_test' with args {} on 4 hosts
2024-07-15 21:38:42,141 - nornir.core.task -    ERROR -      start() - Host 'R4': task 'napalm_ping' failed with traceback:
Traceback (most recent call last):
  File "/Users/maiconlucinda/Documents/Python Code/Network Automation Python/nornir/.venv/lib/python3.11/site-packages/nornir/core/task.py", line 99, in start
    r = self.task(self, **self.params)
        ^^^^^^^^^^^^^^^^^^^^^^^^^^^^^^
  File "/Users/maiconlucinda/Documents/Python Code/Network Automation Python/nornir/.venv/lib/python3.11/site-packages/nornir_napalm/plugins/tasks/napalm_ping.py", line 37, in napalm_ping
    result = device.ping(
             ^^^^^^^^^^^^
  File "/Users/maiconlucinda/Documents/Python Code/Network Automation Python/nornir/.venv/lib/python3.11/site-packages/napalm/ios/ios.py", line 3387, in ping
    output = self._send_command(command)
             ^^^^^^^^^^^^^^^^^^^^^^^^^^^
  File "/Users/maiconlucinda/Documents/Python Code/Network Automation Python/nornir/.venv/lib/python3.11/site-packages/napalm/ios/ios.py", line 209, in _send_command
    output = self.device.send_command(command)
             ^^^^^^^^^^^^^^^^^^^^^^^^^^^^^^^^^
  File "/Users/maiconlucinda/Documents/Python Code/Network Automation Python/nornir/.venv/lib/python3.11/site-packages/netmiko/base_connection.py", line 111, in wrapper_decorator
    return_val = func(self, *args, **kwargs)
                 ^^^^^^^^^^^^^^^^^^^^^^^^^^^
  File "/Users/maiconlucinda/Documents/Python Code/Network Automation Python/nornir/.venv/lib/python3.11/site-packages/netmiko/utilities.py", line 596, in wrapper_decorator
    return func(self, *args, **kwargs)
           ^^^^^^^^^^^^^^^^^^^^^^^^^^^
  File "/Users/maiconlucinda/Documents/Python Code/Network Automation Python/nornir/.venv/lib/python3.11/site-packages/netmiko/base_connection.py", line 1826, in send_command
    raise ReadTimeout(msg)
netmiko.exceptions.ReadTimeout: 
Pattern not detected: 'R4\\#' in output.

Things you might try to fix this:
1. Explicitly set your pattern using the expect_string argument.
2. Increase the read_timeout to a larger value.

You can also look at the Netmiko session_log or debug log for more information.



2024-07-15 21:38:42,142 - nornir.core.task -    ERROR -      start() - Host 'R4': task 'ping_test' failed with traceback:
Traceback (most recent call last):
  File "/Users/maiconlucinda/Documents/Python Code/Network Automation Python/nornir/.venv/lib/python3.11/site-packages/nornir/core/task.py", line 99, in start
    r = self.task(self, **self.params)
        ^^^^^^^^^^^^^^^^^^^^^^^^^^^^^^
  File "/Users/maiconlucinda/Documents/Python Code/Network Automation Python/nornir/14_nornir_napalm_get_ping.py", line 10, in ping_test
    task.run(napalm_ping, dest="192.168.88.76")
  File "/Users/maiconlucinda/Documents/Python Code/Network Automation Python/nornir/.venv/lib/python3.11/site-packages/nornir/core/task.py", line 174, in run
    raise NornirSubTaskError(task=run_task, result=r)
nornir.core.exceptions.NornirSubTaskError: Subtask: napalm_ping (failed)


2024-07-15 21:38:42,150 - nornir.core.task -    ERROR -      start() - Host 'R3': task 'napalm_ping' failed with traceback:
Traceback (most recent call last):
  File "/Users/maiconlucinda/Documents/Python Code/Network Automation Python/nornir/.venv/lib/python3.11/site-packages/nornir/core/task.py", line 99, in start
    r = self.task(self, **self.params)
        ^^^^^^^^^^^^^^^^^^^^^^^^^^^^^^
  File "/Users/maiconlucinda/Documents/Python Code/Network Automation Python/nornir/.venv/lib/python3.11/site-packages/nornir_napalm/plugins/tasks/napalm_ping.py", line 37, in napalm_ping
    result = device.ping(
             ^^^^^^^^^^^^
  File "/Users/maiconlucinda/Documents/Python Code/Network Automation Python/nornir/.venv/lib/python3.11/site-packages/napalm/ios/ios.py", line 3387, in ping
    output = self._send_command(command)
             ^^^^^^^^^^^^^^^^^^^^^^^^^^^
  File "/Users/maiconlucinda/Documents/Python Code/Network Automation Python/nornir/.venv/lib/python3.11/site-packages/napalm/ios/ios.py", line 209, in _send_command
    output = self.device.send_command(command)
             ^^^^^^^^^^^^^^^^^^^^^^^^^^^^^^^^^
  File "/Users/maiconlucinda/Documents/Python Code/Network Automation Python/nornir/.venv/lib/python3.11/site-packages/netmiko/base_connection.py", line 111, in wrapper_decorator
    return_val = func(self, *args, **kwargs)
                 ^^^^^^^^^^^^^^^^^^^^^^^^^^^
  File "/Users/maiconlucinda/Documents/Python Code/Network Automation Python/nornir/.venv/lib/python3.11/site-packages/netmiko/utilities.py", line 596, in wrapper_decorator
    return func(self, *args, **kwargs)
           ^^^^^^^^^^^^^^^^^^^^^^^^^^^
  File "/Users/maiconlucinda/Documents/Python Code/Network Automation Python/nornir/.venv/lib/python3.11/site-packages/netmiko/base_connection.py", line 1826, in send_command
    raise ReadTimeout(msg)
netmiko.exceptions.ReadTimeout: 
Pattern not detected: 'R3\\#' in output.

Things you might try to fix this:
1. Explicitly set your pattern using the expect_string argument.
2. Increase the read_timeout to a larger value.

You can also look at the Netmiko session_log or debug log for more information.



2024-07-15 21:38:42,151 - nornir.core.task -    ERROR -      start() - Host 'R3': task 'ping_test' failed with traceback:
Traceback (most recent call last):
  File "/Users/maiconlucinda/Documents/Python Code/Network Automation Python/nornir/.venv/lib/python3.11/site-packages/nornir/core/task.py", line 99, in start
    r = self.task(self, **self.params)
        ^^^^^^^^^^^^^^^^^^^^^^^^^^^^^^
  File "/Users/maiconlucinda/Documents/Python Code/Network Automation Python/nornir/14_nornir_napalm_get_ping.py", line 10, in ping_test
    task.run(napalm_ping, dest="192.168.88.76")
  File "/Users/maiconlucinda/Documents/Python Code/Network Automation Python/nornir/.venv/lib/python3.11/site-packages/nornir/core/task.py", line 174, in run
    raise NornirSubTaskError(task=run_task, result=r)
nornir.core.exceptions.NornirSubTaskError: Subtask: napalm_ping (failed)


2024-07-15 21:38:42,261 - nornir.core.task -    ERROR -      start() - Host 'R2': task 'napalm_ping' failed with traceback:
Traceback (most recent call last):
  File "/Users/maiconlucinda/Documents/Python Code/Network Automation Python/nornir/.venv/lib/python3.11/site-packages/nornir/core/task.py", line 99, in start
    r = self.task(self, **self.params)
        ^^^^^^^^^^^^^^^^^^^^^^^^^^^^^^
  File "/Users/maiconlucinda/Documents/Python Code/Network Automation Python/nornir/.venv/lib/python3.11/site-packages/nornir_napalm/plugins/tasks/napalm_ping.py", line 37, in napalm_ping
    result = device.ping(
             ^^^^^^^^^^^^
  File "/Users/maiconlucinda/Documents/Python Code/Network Automation Python/nornir/.venv/lib/python3.11/site-packages/napalm/ios/ios.py", line 3387, in ping
    output = self._send_command(command)
             ^^^^^^^^^^^^^^^^^^^^^^^^^^^
  File "/Users/maiconlucinda/Documents/Python Code/Network Automation Python/nornir/.venv/lib/python3.11/site-packages/napalm/ios/ios.py", line 209, in _send_command
    output = self.device.send_command(command)
             ^^^^^^^^^^^^^^^^^^^^^^^^^^^^^^^^^
  File "/Users/maiconlucinda/Documents/Python Code/Network Automation Python/nornir/.venv/lib/python3.11/site-packages/netmiko/base_connection.py", line 111, in wrapper_decorator
    return_val = func(self, *args, **kwargs)
                 ^^^^^^^^^^^^^^^^^^^^^^^^^^^
  File "/Users/maiconlucinda/Documents/Python Code/Network Automation Python/nornir/.venv/lib/python3.11/site-packages/netmiko/utilities.py", line 596, in wrapper_decorator
    return func(self, *args, **kwargs)
           ^^^^^^^^^^^^^^^^^^^^^^^^^^^
  File "/Users/maiconlucinda/Documents/Python Code/Network Automation Python/nornir/.venv/lib/python3.11/site-packages/netmiko/base_connection.py", line 1826, in send_command
    raise ReadTimeout(msg)
netmiko.exceptions.ReadTimeout: 
Pattern not detected: 'R2\\#' in output.

Things you might try to fix this:
1. Explicitly set your pattern using the expect_string argument.
2. Increase the read_timeout to a larger value.

You can also look at the Netmiko session_log or debug log for more information.



2024-07-15 21:38:42,262 - nornir.core.task -    ERROR -      start() - Host 'R2': task 'ping_test' failed with traceback:
Traceback (most recent call last):
  File "/Users/maiconlucinda/Documents/Python Code/Network Automation Python/nornir/.venv/lib/python3.11/site-packages/nornir/core/task.py", line 99, in start
    r = self.task(self, **self.params)
        ^^^^^^^^^^^^^^^^^^^^^^^^^^^^^^
  File "/Users/maiconlucinda/Documents/Python Code/Network Automation Python/nornir/14_nornir_napalm_get_ping.py", line 10, in ping_test
    task.run(napalm_ping, dest="192.168.88.76")
  File "/Users/maiconlucinda/Documents/Python Code/Network Automation Python/nornir/.venv/lib/python3.11/site-packages/nornir/core/task.py", line 174, in run
    raise NornirSubTaskError(task=run_task, result=r)
nornir.core.exceptions.NornirSubTaskError: Subtask: napalm_ping (failed)


2024-07-15 21:38:42,271 - nornir.core.task -    ERROR -      start() - Host 'R1': task 'napalm_ping' failed with traceback:
Traceback (most recent call last):
  File "/Users/maiconlucinda/Documents/Python Code/Network Automation Python/nornir/.venv/lib/python3.11/site-packages/nornir/core/task.py", line 99, in start
    r = self.task(self, **self.params)
        ^^^^^^^^^^^^^^^^^^^^^^^^^^^^^^
  File "/Users/maiconlucinda/Documents/Python Code/Network Automation Python/nornir/.venv/lib/python3.11/site-packages/nornir_napalm/plugins/tasks/napalm_ping.py", line 37, in napalm_ping
    result = device.ping(
             ^^^^^^^^^^^^
  File "/Users/maiconlucinda/Documents/Python Code/Network Automation Python/nornir/.venv/lib/python3.11/site-packages/napalm/ios/ios.py", line 3387, in ping
    output = self._send_command(command)
             ^^^^^^^^^^^^^^^^^^^^^^^^^^^
  File "/Users/maiconlucinda/Documents/Python Code/Network Automation Python/nornir/.venv/lib/python3.11/site-packages/napalm/ios/ios.py", line 209, in _send_command
    output = self.device.send_command(command)
             ^^^^^^^^^^^^^^^^^^^^^^^^^^^^^^^^^
  File "/Users/maiconlucinda/Documents/Python Code/Network Automation Python/nornir/.venv/lib/python3.11/site-packages/netmiko/base_connection.py", line 111, in wrapper_decorator
    return_val = func(self, *args, **kwargs)
                 ^^^^^^^^^^^^^^^^^^^^^^^^^^^
  File "/Users/maiconlucinda/Documents/Python Code/Network Automation Python/nornir/.venv/lib/python3.11/site-packages/netmiko/utilities.py", line 596, in wrapper_decorator
    return func(self, *args, **kwargs)
           ^^^^^^^^^^^^^^^^^^^^^^^^^^^
  File "/Users/maiconlucinda/Documents/Python Code/Network Automation Python/nornir/.venv/lib/python3.11/site-packages/netmiko/base_connection.py", line 1826, in send_command
    raise ReadTimeout(msg)
netmiko.exceptions.ReadTimeout: 
Pattern not detected: 'R1\\#' in output.

Things you might try to fix this:
1. Explicitly set your pattern using the expect_string argument.
2. Increase the read_timeout to a larger value.

You can also look at the Netmiko session_log or debug log for more information.



2024-07-15 21:38:42,272 - nornir.core.task -    ERROR -      start() - Host 'R1': task 'ping_test' failed with traceback:
Traceback (most recent call last):
  File "/Users/maiconlucinda/Documents/Python Code/Network Automation Python/nornir/.venv/lib/python3.11/site-packages/nornir/core/task.py", line 99, in start
    r = self.task(self, **self.params)
        ^^^^^^^^^^^^^^^^^^^^^^^^^^^^^^
  File "/Users/maiconlucinda/Documents/Python Code/Network Automation Python/nornir/14_nornir_napalm_get_ping.py", line 10, in ping_test
    task.run(napalm_ping, dest="192.168.88.76")
  File "/Users/maiconlucinda/Documents/Python Code/Network Automation Python/nornir/.venv/lib/python3.11/site-packages/nornir/core/task.py", line 174, in run
    raise NornirSubTaskError(task=run_task, result=r)
nornir.core.exceptions.NornirSubTaskError: Subtask: napalm_ping (failed)


2024-07-15 21:39:08,395 -  nornir.core -     INFO -        run() - Running task 'ping_test' with args {} on 4 hosts
2024-07-15 21:39:18,884 -  nornir.core -     INFO -        run() - Running task 'ping_test' with args {} on 4 hosts
2024-07-15 21:39:31,597 - nornir.core.task -    ERROR -      start() - Host 'R1': task 'napalm_ping' failed with traceback:
Traceback (most recent call last):
  File "/Users/maiconlucinda/Documents/Python Code/Network Automation Python/nornir/.venv/lib/python3.11/site-packages/nornir/core/task.py", line 99, in start
    r = self.task(self, **self.params)
        ^^^^^^^^^^^^^^^^^^^^^^^^^^^^^^
  File "/Users/maiconlucinda/Documents/Python Code/Network Automation Python/nornir/.venv/lib/python3.11/site-packages/nornir_napalm/plugins/tasks/napalm_ping.py", line 37, in napalm_ping
    result = device.ping(
             ^^^^^^^^^^^^
  File "/Users/maiconlucinda/Documents/Python Code/Network Automation Python/nornir/.venv/lib/python3.11/site-packages/napalm/ios/ios.py", line 3387, in ping
    output = self._send_command(command)
             ^^^^^^^^^^^^^^^^^^^^^^^^^^^
  File "/Users/maiconlucinda/Documents/Python Code/Network Automation Python/nornir/.venv/lib/python3.11/site-packages/napalm/ios/ios.py", line 209, in _send_command
    output = self.device.send_command(command)
             ^^^^^^^^^^^^^^^^^^^^^^^^^^^^^^^^^
  File "/Users/maiconlucinda/Documents/Python Code/Network Automation Python/nornir/.venv/lib/python3.11/site-packages/netmiko/base_connection.py", line 111, in wrapper_decorator
    return_val = func(self, *args, **kwargs)
                 ^^^^^^^^^^^^^^^^^^^^^^^^^^^
  File "/Users/maiconlucinda/Documents/Python Code/Network Automation Python/nornir/.venv/lib/python3.11/site-packages/netmiko/utilities.py", line 596, in wrapper_decorator
    return func(self, *args, **kwargs)
           ^^^^^^^^^^^^^^^^^^^^^^^^^^^
  File "/Users/maiconlucinda/Documents/Python Code/Network Automation Python/nornir/.venv/lib/python3.11/site-packages/netmiko/base_connection.py", line 1826, in send_command
    raise ReadTimeout(msg)
netmiko.exceptions.ReadTimeout: 
Pattern not detected: 'R1\\#' in output.

Things you might try to fix this:
1. Explicitly set your pattern using the expect_string argument.
2. Increase the read_timeout to a larger value.

You can also look at the Netmiko session_log or debug log for more information.



2024-07-15 21:39:31,598 - nornir.core.task -    ERROR -      start() - Host 'R1': task 'ping_test' failed with traceback:
Traceback (most recent call last):
  File "/Users/maiconlucinda/Documents/Python Code/Network Automation Python/nornir/.venv/lib/python3.11/site-packages/nornir/core/task.py", line 99, in start
    r = self.task(self, **self.params)
        ^^^^^^^^^^^^^^^^^^^^^^^^^^^^^^
  File "/Users/maiconlucinda/Documents/Python Code/Network Automation Python/nornir/14_nornir_napalm_get_ping.py", line 10, in ping_test
    task.run(napalm_ping, dest="192.168.88.2")
  File "/Users/maiconlucinda/Documents/Python Code/Network Automation Python/nornir/.venv/lib/python3.11/site-packages/nornir/core/task.py", line 174, in run
    raise NornirSubTaskError(task=run_task, result=r)
nornir.core.exceptions.NornirSubTaskError: Subtask: napalm_ping (failed)


2024-07-15 21:39:31,599 - nornir.core.task -    ERROR -      start() - Host 'R2': task 'napalm_ping' failed with traceback:
Traceback (most recent call last):
  File "/Users/maiconlucinda/Documents/Python Code/Network Automation Python/nornir/.venv/lib/python3.11/site-packages/nornir/core/task.py", line 99, in start
    r = self.task(self, **self.params)
        ^^^^^^^^^^^^^^^^^^^^^^^^^^^^^^
  File "/Users/maiconlucinda/Documents/Python Code/Network Automation Python/nornir/.venv/lib/python3.11/site-packages/nornir_napalm/plugins/tasks/napalm_ping.py", line 37, in napalm_ping
    result = device.ping(
             ^^^^^^^^^^^^
  File "/Users/maiconlucinda/Documents/Python Code/Network Automation Python/nornir/.venv/lib/python3.11/site-packages/napalm/ios/ios.py", line 3387, in ping
    output = self._send_command(command)
             ^^^^^^^^^^^^^^^^^^^^^^^^^^^
  File "/Users/maiconlucinda/Documents/Python Code/Network Automation Python/nornir/.venv/lib/python3.11/site-packages/napalm/ios/ios.py", line 209, in _send_command
    output = self.device.send_command(command)
             ^^^^^^^^^^^^^^^^^^^^^^^^^^^^^^^^^
  File "/Users/maiconlucinda/Documents/Python Code/Network Automation Python/nornir/.venv/lib/python3.11/site-packages/netmiko/base_connection.py", line 111, in wrapper_decorator
    return_val = func(self, *args, **kwargs)
                 ^^^^^^^^^^^^^^^^^^^^^^^^^^^
  File "/Users/maiconlucinda/Documents/Python Code/Network Automation Python/nornir/.venv/lib/python3.11/site-packages/netmiko/utilities.py", line 596, in wrapper_decorator
    return func(self, *args, **kwargs)
           ^^^^^^^^^^^^^^^^^^^^^^^^^^^
  File "/Users/maiconlucinda/Documents/Python Code/Network Automation Python/nornir/.venv/lib/python3.11/site-packages/netmiko/base_connection.py", line 1826, in send_command
    raise ReadTimeout(msg)
netmiko.exceptions.ReadTimeout: 
Pattern not detected: 'R2\\#' in output.

Things you might try to fix this:
1. Explicitly set your pattern using the expect_string argument.
2. Increase the read_timeout to a larger value.

You can also look at the Netmiko session_log or debug log for more information.



2024-07-15 21:39:31,599 - nornir.core.task -    ERROR -      start() - Host 'R2': task 'ping_test' failed with traceback:
Traceback (most recent call last):
  File "/Users/maiconlucinda/Documents/Python Code/Network Automation Python/nornir/.venv/lib/python3.11/site-packages/nornir/core/task.py", line 99, in start
    r = self.task(self, **self.params)
        ^^^^^^^^^^^^^^^^^^^^^^^^^^^^^^
  File "/Users/maiconlucinda/Documents/Python Code/Network Automation Python/nornir/14_nornir_napalm_get_ping.py", line 10, in ping_test
    task.run(napalm_ping, dest="192.168.88.2")
  File "/Users/maiconlucinda/Documents/Python Code/Network Automation Python/nornir/.venv/lib/python3.11/site-packages/nornir/core/task.py", line 174, in run
    raise NornirSubTaskError(task=run_task, result=r)
nornir.core.exceptions.NornirSubTaskError: Subtask: napalm_ping (failed)


2024-07-15 21:39:31,626 - nornir.core.task -    ERROR -      start() - Host 'R3': task 'napalm_ping' failed with traceback:
Traceback (most recent call last):
  File "/Users/maiconlucinda/Documents/Python Code/Network Automation Python/nornir/.venv/lib/python3.11/site-packages/nornir/core/task.py", line 99, in start
    r = self.task(self, **self.params)
        ^^^^^^^^^^^^^^^^^^^^^^^^^^^^^^
  File "/Users/maiconlucinda/Documents/Python Code/Network Automation Python/nornir/.venv/lib/python3.11/site-packages/nornir_napalm/plugins/tasks/napalm_ping.py", line 37, in napalm_ping
    result = device.ping(
             ^^^^^^^^^^^^
  File "/Users/maiconlucinda/Documents/Python Code/Network Automation Python/nornir/.venv/lib/python3.11/site-packages/napalm/ios/ios.py", line 3387, in ping
    output = self._send_command(command)
             ^^^^^^^^^^^^^^^^^^^^^^^^^^^
  File "/Users/maiconlucinda/Documents/Python Code/Network Automation Python/nornir/.venv/lib/python3.11/site-packages/napalm/ios/ios.py", line 209, in _send_command
    output = self.device.send_command(command)
             ^^^^^^^^^^^^^^^^^^^^^^^^^^^^^^^^^
  File "/Users/maiconlucinda/Documents/Python Code/Network Automation Python/nornir/.venv/lib/python3.11/site-packages/netmiko/base_connection.py", line 111, in wrapper_decorator
    return_val = func(self, *args, **kwargs)
                 ^^^^^^^^^^^^^^^^^^^^^^^^^^^
  File "/Users/maiconlucinda/Documents/Python Code/Network Automation Python/nornir/.venv/lib/python3.11/site-packages/netmiko/utilities.py", line 596, in wrapper_decorator
    return func(self, *args, **kwargs)
           ^^^^^^^^^^^^^^^^^^^^^^^^^^^
  File "/Users/maiconlucinda/Documents/Python Code/Network Automation Python/nornir/.venv/lib/python3.11/site-packages/netmiko/base_connection.py", line 1826, in send_command
    raise ReadTimeout(msg)
netmiko.exceptions.ReadTimeout: 
Pattern not detected: 'R3\\#' in output.

Things you might try to fix this:
1. Explicitly set your pattern using the expect_string argument.
2. Increase the read_timeout to a larger value.

You can also look at the Netmiko session_log or debug log for more information.



2024-07-15 21:39:31,627 - nornir.core.task -    ERROR -      start() - Host 'R3': task 'ping_test' failed with traceback:
Traceback (most recent call last):
  File "/Users/maiconlucinda/Documents/Python Code/Network Automation Python/nornir/.venv/lib/python3.11/site-packages/nornir/core/task.py", line 99, in start
    r = self.task(self, **self.params)
        ^^^^^^^^^^^^^^^^^^^^^^^^^^^^^^
  File "/Users/maiconlucinda/Documents/Python Code/Network Automation Python/nornir/14_nornir_napalm_get_ping.py", line 10, in ping_test
    task.run(napalm_ping, dest="192.168.88.2")
  File "/Users/maiconlucinda/Documents/Python Code/Network Automation Python/nornir/.venv/lib/python3.11/site-packages/nornir/core/task.py", line 174, in run
    raise NornirSubTaskError(task=run_task, result=r)
nornir.core.exceptions.NornirSubTaskError: Subtask: napalm_ping (failed)


2024-07-15 21:39:31,627 - nornir.core.task -    ERROR -      start() - Host 'R4': task 'napalm_ping' failed with traceback:
Traceback (most recent call last):
  File "/Users/maiconlucinda/Documents/Python Code/Network Automation Python/nornir/.venv/lib/python3.11/site-packages/nornir/core/task.py", line 99, in start
    r = self.task(self, **self.params)
        ^^^^^^^^^^^^^^^^^^^^^^^^^^^^^^
  File "/Users/maiconlucinda/Documents/Python Code/Network Automation Python/nornir/.venv/lib/python3.11/site-packages/nornir_napalm/plugins/tasks/napalm_ping.py", line 37, in napalm_ping
    result = device.ping(
             ^^^^^^^^^^^^
  File "/Users/maiconlucinda/Documents/Python Code/Network Automation Python/nornir/.venv/lib/python3.11/site-packages/napalm/ios/ios.py", line 3387, in ping
    output = self._send_command(command)
             ^^^^^^^^^^^^^^^^^^^^^^^^^^^
  File "/Users/maiconlucinda/Documents/Python Code/Network Automation Python/nornir/.venv/lib/python3.11/site-packages/napalm/ios/ios.py", line 209, in _send_command
    output = self.device.send_command(command)
             ^^^^^^^^^^^^^^^^^^^^^^^^^^^^^^^^^
  File "/Users/maiconlucinda/Documents/Python Code/Network Automation Python/nornir/.venv/lib/python3.11/site-packages/netmiko/base_connection.py", line 111, in wrapper_decorator
    return_val = func(self, *args, **kwargs)
                 ^^^^^^^^^^^^^^^^^^^^^^^^^^^
  File "/Users/maiconlucinda/Documents/Python Code/Network Automation Python/nornir/.venv/lib/python3.11/site-packages/netmiko/utilities.py", line 596, in wrapper_decorator
    return func(self, *args, **kwargs)
           ^^^^^^^^^^^^^^^^^^^^^^^^^^^
  File "/Users/maiconlucinda/Documents/Python Code/Network Automation Python/nornir/.venv/lib/python3.11/site-packages/netmiko/base_connection.py", line 1826, in send_command
    raise ReadTimeout(msg)
netmiko.exceptions.ReadTimeout: 
Pattern not detected: 'R4\\#' in output.

Things you might try to fix this:
1. Explicitly set your pattern using the expect_string argument.
2. Increase the read_timeout to a larger value.

You can also look at the Netmiko session_log or debug log for more information.



2024-07-15 21:39:31,628 - nornir.core.task -    ERROR -      start() - Host 'R4': task 'ping_test' failed with traceback:
Traceback (most recent call last):
  File "/Users/maiconlucinda/Documents/Python Code/Network Automation Python/nornir/.venv/lib/python3.11/site-packages/nornir/core/task.py", line 99, in start
    r = self.task(self, **self.params)
        ^^^^^^^^^^^^^^^^^^^^^^^^^^^^^^
  File "/Users/maiconlucinda/Documents/Python Code/Network Automation Python/nornir/14_nornir_napalm_get_ping.py", line 10, in ping_test
    task.run(napalm_ping, dest="192.168.88.2")
  File "/Users/maiconlucinda/Documents/Python Code/Network Automation Python/nornir/.venv/lib/python3.11/site-packages/nornir/core/task.py", line 174, in run
    raise NornirSubTaskError(task=run_task, result=r)
nornir.core.exceptions.NornirSubTaskError: Subtask: napalm_ping (failed)


2024-07-15 22:47:02,117 -  nornir.core -     INFO -        run() - Running task 'commit_flash' with args {} on 4 hosts
2024-07-15 22:47:34,170 - nornir.core.task -    ERROR -      start() - Host 'R3': task 'send_interactive' failed with traceback:
Traceback (most recent call last):
  File "/Users/maiconlucinda/Documents/Python Code/Network Automation Python/nornir/.venv/lib/python3.11/site-packages/nornir/core/task.py", line 99, in start
    r = self.task(self, **self.params)
        ^^^^^^^^^^^^^^^^^^^^^^^^^^^^^^
  File "/Users/maiconlucinda/Documents/Python Code/Network Automation Python/nornir/.venv/lib/python3.11/site-packages/nornir_scrapli/tasks/core/send_interactive.py", line 80, in send_interactive
    scrapli_response = scrapli_conn.send_interactive(
                       ^^^^^^^^^^^^^^^^^^^^^^^^^^^^^^
  File "/Users/maiconlucinda/Documents/Python Code/Network Automation Python/nornir/.venv/lib/python3.11/site-packages/scrapli/driver/network/sync_driver.py", line 460, in send_interactive
    response: Response = super().send_interactive(
                         ^^^^^^^^^^^^^^^^^^^^^^^^^
  File "/Users/maiconlucinda/Documents/Python Code/Network Automation Python/nornir/.venv/lib/python3.11/site-packages/scrapli/decorators.py", line 306, in decorate
    result = wrapped_func(*args, **kwargs)
             ^^^^^^^^^^^^^^^^^^^^^^^^^^^^^
  File "/Users/maiconlucinda/Documents/Python Code/Network Automation Python/nornir/.venv/lib/python3.11/site-packages/scrapli/driver/generic/sync_driver.py", line 462, in send_interactive
    raw_response, processed_response = self.channel.send_inputs_interact(
                                       ^^^^^^^^^^^^^^^^^^^^^^^^^^^^^^^^^^
  File "/Users/maiconlucinda/Documents/Python Code/Network Automation Python/nornir/.venv/lib/python3.11/site-packages/scrapli/decorators.py", line 223, in decorate
    return _multiprocessing_timeout(
           ^^^^^^^^^^^^^^^^^^^^^^^^^
  File "/Users/maiconlucinda/Documents/Python Code/Network Automation Python/nornir/.venv/lib/python3.11/site-packages/scrapli/decorators.py", line 109, in _multiprocessing_timeout
    return _handle_timeout(
           ^^^^^^^^^^^^^^^^
  File "/Users/maiconlucinda/Documents/Python Code/Network Automation Python/nornir/.venv/lib/python3.11/site-packages/scrapli/decorators.py", line 141, in _handle_timeout
    raise ScrapliTimeout(message)
scrapli.exceptions.ScrapliTimeout: timed out sending interactive input to device

2024-07-15 22:47:34,172 - nornir.core.task -    ERROR -      start() - Host 'R3': task 'commit_flash' failed with traceback:
Traceback (most recent call last):
  File "/Users/maiconlucinda/Documents/Python Code/Network Automation Python/nornir/.venv/lib/python3.11/site-packages/nornir/core/task.py", line 99, in start
    r = self.task(self, **self.params)
        ^^^^^^^^^^^^^^^^^^^^^^^^^^^^^^
  File "/Users/maiconlucinda/Documents/Python Code/Network Automation Python/nornir/15_nornir_scarpli_interactive.py", line 10, in commit_flash
    task.run(task=send_interactive, interact_events=cmds)
  File "/Users/maiconlucinda/Documents/Python Code/Network Automation Python/nornir/.venv/lib/python3.11/site-packages/nornir/core/task.py", line 174, in run
    raise NornirSubTaskError(task=run_task, result=r)
nornir.core.exceptions.NornirSubTaskError: Subtask: send_interactive (failed)


2024-07-15 22:47:34,181 - nornir.core.task -    ERROR -      start() - Host 'R2': task 'send_interactive' failed with traceback:
Traceback (most recent call last):
  File "/Users/maiconlucinda/Documents/Python Code/Network Automation Python/nornir/.venv/lib/python3.11/site-packages/nornir/core/task.py", line 99, in start
    r = self.task(self, **self.params)
        ^^^^^^^^^^^^^^^^^^^^^^^^^^^^^^
  File "/Users/maiconlucinda/Documents/Python Code/Network Automation Python/nornir/.venv/lib/python3.11/site-packages/nornir_scrapli/tasks/core/send_interactive.py", line 80, in send_interactive
    scrapli_response = scrapli_conn.send_interactive(
                       ^^^^^^^^^^^^^^^^^^^^^^^^^^^^^^
  File "/Users/maiconlucinda/Documents/Python Code/Network Automation Python/nornir/.venv/lib/python3.11/site-packages/scrapli/driver/network/sync_driver.py", line 460, in send_interactive
    response: Response = super().send_interactive(
                         ^^^^^^^^^^^^^^^^^^^^^^^^^
  File "/Users/maiconlucinda/Documents/Python Code/Network Automation Python/nornir/.venv/lib/python3.11/site-packages/scrapli/decorators.py", line 306, in decorate
    result = wrapped_func(*args, **kwargs)
             ^^^^^^^^^^^^^^^^^^^^^^^^^^^^^
  File "/Users/maiconlucinda/Documents/Python Code/Network Automation Python/nornir/.venv/lib/python3.11/site-packages/scrapli/driver/generic/sync_driver.py", line 462, in send_interactive
    raw_response, processed_response = self.channel.send_inputs_interact(
                                       ^^^^^^^^^^^^^^^^^^^^^^^^^^^^^^^^^^
  File "/Users/maiconlucinda/Documents/Python Code/Network Automation Python/nornir/.venv/lib/python3.11/site-packages/scrapli/decorators.py", line 223, in decorate
    return _multiprocessing_timeout(
           ^^^^^^^^^^^^^^^^^^^^^^^^^
  File "/Users/maiconlucinda/Documents/Python Code/Network Automation Python/nornir/.venv/lib/python3.11/site-packages/scrapli/decorators.py", line 109, in _multiprocessing_timeout
    return _handle_timeout(
           ^^^^^^^^^^^^^^^^
  File "/Users/maiconlucinda/Documents/Python Code/Network Automation Python/nornir/.venv/lib/python3.11/site-packages/scrapli/decorators.py", line 141, in _handle_timeout
    raise ScrapliTimeout(message)
scrapli.exceptions.ScrapliTimeout: timed out sending interactive input to device

2024-07-15 22:47:34,182 - nornir.core.task -    ERROR -      start() - Host 'R2': task 'commit_flash' failed with traceback:
Traceback (most recent call last):
  File "/Users/maiconlucinda/Documents/Python Code/Network Automation Python/nornir/.venv/lib/python3.11/site-packages/nornir/core/task.py", line 99, in start
    r = self.task(self, **self.params)
        ^^^^^^^^^^^^^^^^^^^^^^^^^^^^^^
  File "/Users/maiconlucinda/Documents/Python Code/Network Automation Python/nornir/15_nornir_scarpli_interactive.py", line 10, in commit_flash
    task.run(task=send_interactive, interact_events=cmds)
  File "/Users/maiconlucinda/Documents/Python Code/Network Automation Python/nornir/.venv/lib/python3.11/site-packages/nornir/core/task.py", line 174, in run
    raise NornirSubTaskError(task=run_task, result=r)
nornir.core.exceptions.NornirSubTaskError: Subtask: send_interactive (failed)


2024-07-15 22:47:34,192 - nornir.core.task -    ERROR -      start() - Host 'R4': task 'send_interactive' failed with traceback:
Traceback (most recent call last):
  File "/Users/maiconlucinda/Documents/Python Code/Network Automation Python/nornir/.venv/lib/python3.11/site-packages/nornir/core/task.py", line 99, in start
    r = self.task(self, **self.params)
        ^^^^^^^^^^^^^^^^^^^^^^^^^^^^^^
  File "/Users/maiconlucinda/Documents/Python Code/Network Automation Python/nornir/.venv/lib/python3.11/site-packages/nornir_scrapli/tasks/core/send_interactive.py", line 80, in send_interactive
    scrapli_response = scrapli_conn.send_interactive(
                       ^^^^^^^^^^^^^^^^^^^^^^^^^^^^^^
  File "/Users/maiconlucinda/Documents/Python Code/Network Automation Python/nornir/.venv/lib/python3.11/site-packages/scrapli/driver/network/sync_driver.py", line 460, in send_interactive
    response: Response = super().send_interactive(
                         ^^^^^^^^^^^^^^^^^^^^^^^^^
  File "/Users/maiconlucinda/Documents/Python Code/Network Automation Python/nornir/.venv/lib/python3.11/site-packages/scrapli/decorators.py", line 306, in decorate
    result = wrapped_func(*args, **kwargs)
             ^^^^^^^^^^^^^^^^^^^^^^^^^^^^^
  File "/Users/maiconlucinda/Documents/Python Code/Network Automation Python/nornir/.venv/lib/python3.11/site-packages/scrapli/driver/generic/sync_driver.py", line 462, in send_interactive
    raw_response, processed_response = self.channel.send_inputs_interact(
                                       ^^^^^^^^^^^^^^^^^^^^^^^^^^^^^^^^^^
  File "/Users/maiconlucinda/Documents/Python Code/Network Automation Python/nornir/.venv/lib/python3.11/site-packages/scrapli/decorators.py", line 223, in decorate
    return _multiprocessing_timeout(
           ^^^^^^^^^^^^^^^^^^^^^^^^^
  File "/Users/maiconlucinda/Documents/Python Code/Network Automation Python/nornir/.venv/lib/python3.11/site-packages/scrapli/decorators.py", line 109, in _multiprocessing_timeout
    return _handle_timeout(
           ^^^^^^^^^^^^^^^^
  File "/Users/maiconlucinda/Documents/Python Code/Network Automation Python/nornir/.venv/lib/python3.11/site-packages/scrapli/decorators.py", line 141, in _handle_timeout
    raise ScrapliTimeout(message)
scrapli.exceptions.ScrapliTimeout: timed out sending interactive input to device

2024-07-15 22:47:34,193 - nornir.core.task -    ERROR -      start() - Host 'R4': task 'commit_flash' failed with traceback:
Traceback (most recent call last):
  File "/Users/maiconlucinda/Documents/Python Code/Network Automation Python/nornir/.venv/lib/python3.11/site-packages/nornir/core/task.py", line 99, in start
    r = self.task(self, **self.params)
        ^^^^^^^^^^^^^^^^^^^^^^^^^^^^^^
  File "/Users/maiconlucinda/Documents/Python Code/Network Automation Python/nornir/15_nornir_scarpli_interactive.py", line 10, in commit_flash
    task.run(task=send_interactive, interact_events=cmds)
  File "/Users/maiconlucinda/Documents/Python Code/Network Automation Python/nornir/.venv/lib/python3.11/site-packages/nornir/core/task.py", line 174, in run
    raise NornirSubTaskError(task=run_task, result=r)
nornir.core.exceptions.NornirSubTaskError: Subtask: send_interactive (failed)


2024-07-15 22:47:34,209 - nornir.core.task -    ERROR -      start() - Host 'R1': task 'send_interactive' failed with traceback:
Traceback (most recent call last):
  File "/Users/maiconlucinda/Documents/Python Code/Network Automation Python/nornir/.venv/lib/python3.11/site-packages/nornir/core/task.py", line 99, in start
    r = self.task(self, **self.params)
        ^^^^^^^^^^^^^^^^^^^^^^^^^^^^^^
  File "/Users/maiconlucinda/Documents/Python Code/Network Automation Python/nornir/.venv/lib/python3.11/site-packages/nornir_scrapli/tasks/core/send_interactive.py", line 80, in send_interactive
    scrapli_response = scrapli_conn.send_interactive(
                       ^^^^^^^^^^^^^^^^^^^^^^^^^^^^^^
  File "/Users/maiconlucinda/Documents/Python Code/Network Automation Python/nornir/.venv/lib/python3.11/site-packages/scrapli/driver/network/sync_driver.py", line 460, in send_interactive
    response: Response = super().send_interactive(
                         ^^^^^^^^^^^^^^^^^^^^^^^^^
  File "/Users/maiconlucinda/Documents/Python Code/Network Automation Python/nornir/.venv/lib/python3.11/site-packages/scrapli/decorators.py", line 306, in decorate
    result = wrapped_func(*args, **kwargs)
             ^^^^^^^^^^^^^^^^^^^^^^^^^^^^^
  File "/Users/maiconlucinda/Documents/Python Code/Network Automation Python/nornir/.venv/lib/python3.11/site-packages/scrapli/driver/generic/sync_driver.py", line 462, in send_interactive
    raw_response, processed_response = self.channel.send_inputs_interact(
                                       ^^^^^^^^^^^^^^^^^^^^^^^^^^^^^^^^^^
  File "/Users/maiconlucinda/Documents/Python Code/Network Automation Python/nornir/.venv/lib/python3.11/site-packages/scrapli/decorators.py", line 223, in decorate
    return _multiprocessing_timeout(
           ^^^^^^^^^^^^^^^^^^^^^^^^^
  File "/Users/maiconlucinda/Documents/Python Code/Network Automation Python/nornir/.venv/lib/python3.11/site-packages/scrapli/decorators.py", line 109, in _multiprocessing_timeout
    return _handle_timeout(
           ^^^^^^^^^^^^^^^^
  File "/Users/maiconlucinda/Documents/Python Code/Network Automation Python/nornir/.venv/lib/python3.11/site-packages/scrapli/decorators.py", line 141, in _handle_timeout
    raise ScrapliTimeout(message)
scrapli.exceptions.ScrapliTimeout: timed out sending interactive input to device

2024-07-15 22:47:34,210 - nornir.core.task -    ERROR -      start() - Host 'R1': task 'commit_flash' failed with traceback:
Traceback (most recent call last):
  File "/Users/maiconlucinda/Documents/Python Code/Network Automation Python/nornir/.venv/lib/python3.11/site-packages/nornir/core/task.py", line 99, in start
    r = self.task(self, **self.params)
        ^^^^^^^^^^^^^^^^^^^^^^^^^^^^^^
  File "/Users/maiconlucinda/Documents/Python Code/Network Automation Python/nornir/15_nornir_scarpli_interactive.py", line 10, in commit_flash
    task.run(task=send_interactive, interact_events=cmds)
  File "/Users/maiconlucinda/Documents/Python Code/Network Automation Python/nornir/.venv/lib/python3.11/site-packages/nornir/core/task.py", line 174, in run
    raise NornirSubTaskError(task=run_task, result=r)
nornir.core.exceptions.NornirSubTaskError: Subtask: send_interactive (failed)


2024-07-15 22:48:42,421 -  nornir.core -     INFO -        run() - Running task 'ping_test' with args {} on 4 hosts
2024-07-15 22:48:54,335 - nornir.core.task -    ERROR -      start() - Host 'R4': task 'napalm_ping' failed with traceback:
Traceback (most recent call last):
  File "/Users/maiconlucinda/Documents/Python Code/Network Automation Python/nornir/.venv/lib/python3.11/site-packages/nornir/core/task.py", line 99, in start
    r = self.task(self, **self.params)
        ^^^^^^^^^^^^^^^^^^^^^^^^^^^^^^
  File "/Users/maiconlucinda/Documents/Python Code/Network Automation Python/nornir/.venv/lib/python3.11/site-packages/nornir_napalm/plugins/tasks/napalm_ping.py", line 37, in napalm_ping
    result = device.ping(
             ^^^^^^^^^^^^
  File "/Users/maiconlucinda/Documents/Python Code/Network Automation Python/nornir/.venv/lib/python3.11/site-packages/napalm/ios/ios.py", line 3387, in ping
    output = self._send_command(command)
             ^^^^^^^^^^^^^^^^^^^^^^^^^^^
  File "/Users/maiconlucinda/Documents/Python Code/Network Automation Python/nornir/.venv/lib/python3.11/site-packages/napalm/ios/ios.py", line 209, in _send_command
    output = self.device.send_command(command)
             ^^^^^^^^^^^^^^^^^^^^^^^^^^^^^^^^^
  File "/Users/maiconlucinda/Documents/Python Code/Network Automation Python/nornir/.venv/lib/python3.11/site-packages/netmiko/base_connection.py", line 111, in wrapper_decorator
    return_val = func(self, *args, **kwargs)
                 ^^^^^^^^^^^^^^^^^^^^^^^^^^^
  File "/Users/maiconlucinda/Documents/Python Code/Network Automation Python/nornir/.venv/lib/python3.11/site-packages/netmiko/utilities.py", line 596, in wrapper_decorator
    return func(self, *args, **kwargs)
           ^^^^^^^^^^^^^^^^^^^^^^^^^^^
  File "/Users/maiconlucinda/Documents/Python Code/Network Automation Python/nornir/.venv/lib/python3.11/site-packages/netmiko/base_connection.py", line 1826, in send_command
    raise ReadTimeout(msg)
netmiko.exceptions.ReadTimeout: 
Pattern not detected: 'R4\\#' in output.

Things you might try to fix this:
1. Explicitly set your pattern using the expect_string argument.
2. Increase the read_timeout to a larger value.

You can also look at the Netmiko session_log or debug log for more information.



2024-07-15 22:48:54,336 - nornir.core.task -    ERROR -      start() - Host 'R3': task 'napalm_ping' failed with traceback:
Traceback (most recent call last):
  File "/Users/maiconlucinda/Documents/Python Code/Network Automation Python/nornir/.venv/lib/python3.11/site-packages/nornir/core/task.py", line 99, in start
    r = self.task(self, **self.params)
        ^^^^^^^^^^^^^^^^^^^^^^^^^^^^^^
  File "/Users/maiconlucinda/Documents/Python Code/Network Automation Python/nornir/.venv/lib/python3.11/site-packages/nornir_napalm/plugins/tasks/napalm_ping.py", line 37, in napalm_ping
    result = device.ping(
             ^^^^^^^^^^^^
  File "/Users/maiconlucinda/Documents/Python Code/Network Automation Python/nornir/.venv/lib/python3.11/site-packages/napalm/ios/ios.py", line 3387, in ping
    output = self._send_command(command)
             ^^^^^^^^^^^^^^^^^^^^^^^^^^^
  File "/Users/maiconlucinda/Documents/Python Code/Network Automation Python/nornir/.venv/lib/python3.11/site-packages/napalm/ios/ios.py", line 209, in _send_command
    output = self.device.send_command(command)
             ^^^^^^^^^^^^^^^^^^^^^^^^^^^^^^^^^
  File "/Users/maiconlucinda/Documents/Python Code/Network Automation Python/nornir/.venv/lib/python3.11/site-packages/netmiko/base_connection.py", line 111, in wrapper_decorator
    return_val = func(self, *args, **kwargs)
                 ^^^^^^^^^^^^^^^^^^^^^^^^^^^
  File "/Users/maiconlucinda/Documents/Python Code/Network Automation Python/nornir/.venv/lib/python3.11/site-packages/netmiko/utilities.py", line 596, in wrapper_decorator
    return func(self, *args, **kwargs)
           ^^^^^^^^^^^^^^^^^^^^^^^^^^^
  File "/Users/maiconlucinda/Documents/Python Code/Network Automation Python/nornir/.venv/lib/python3.11/site-packages/netmiko/base_connection.py", line 1826, in send_command
    raise ReadTimeout(msg)
netmiko.exceptions.ReadTimeout: 
Pattern not detected: 'R3\\#' in output.

Things you might try to fix this:
1. Explicitly set your pattern using the expect_string argument.
2. Increase the read_timeout to a larger value.

You can also look at the Netmiko session_log or debug log for more information.



2024-07-15 22:48:54,336 - nornir.core.task -    ERROR -      start() - Host 'R1': task 'napalm_ping' failed with traceback:
Traceback (most recent call last):
  File "/Users/maiconlucinda/Documents/Python Code/Network Automation Python/nornir/.venv/lib/python3.11/site-packages/nornir/core/task.py", line 99, in start
    r = self.task(self, **self.params)
        ^^^^^^^^^^^^^^^^^^^^^^^^^^^^^^
  File "/Users/maiconlucinda/Documents/Python Code/Network Automation Python/nornir/.venv/lib/python3.11/site-packages/nornir_napalm/plugins/tasks/napalm_ping.py", line 37, in napalm_ping
    result = device.ping(
             ^^^^^^^^^^^^
  File "/Users/maiconlucinda/Documents/Python Code/Network Automation Python/nornir/.venv/lib/python3.11/site-packages/napalm/ios/ios.py", line 3387, in ping
    output = self._send_command(command)
             ^^^^^^^^^^^^^^^^^^^^^^^^^^^
  File "/Users/maiconlucinda/Documents/Python Code/Network Automation Python/nornir/.venv/lib/python3.11/site-packages/napalm/ios/ios.py", line 209, in _send_command
    output = self.device.send_command(command)
             ^^^^^^^^^^^^^^^^^^^^^^^^^^^^^^^^^
  File "/Users/maiconlucinda/Documents/Python Code/Network Automation Python/nornir/.venv/lib/python3.11/site-packages/netmiko/base_connection.py", line 111, in wrapper_decorator
    return_val = func(self, *args, **kwargs)
                 ^^^^^^^^^^^^^^^^^^^^^^^^^^^
  File "/Users/maiconlucinda/Documents/Python Code/Network Automation Python/nornir/.venv/lib/python3.11/site-packages/netmiko/utilities.py", line 596, in wrapper_decorator
    return func(self, *args, **kwargs)
           ^^^^^^^^^^^^^^^^^^^^^^^^^^^
  File "/Users/maiconlucinda/Documents/Python Code/Network Automation Python/nornir/.venv/lib/python3.11/site-packages/netmiko/base_connection.py", line 1826, in send_command
    raise ReadTimeout(msg)
netmiko.exceptions.ReadTimeout: 
Pattern not detected: 'R1\\#' in output.

Things you might try to fix this:
1. Explicitly set your pattern using the expect_string argument.
2. Increase the read_timeout to a larger value.

You can also look at the Netmiko session_log or debug log for more information.



2024-07-15 22:48:54,337 - nornir.core.task -    ERROR -      start() - Host 'R2': task 'napalm_ping' failed with traceback:
Traceback (most recent call last):
  File "/Users/maiconlucinda/Documents/Python Code/Network Automation Python/nornir/.venv/lib/python3.11/site-packages/nornir/core/task.py", line 99, in start
    r = self.task(self, **self.params)
        ^^^^^^^^^^^^^^^^^^^^^^^^^^^^^^
  File "/Users/maiconlucinda/Documents/Python Code/Network Automation Python/nornir/.venv/lib/python3.11/site-packages/nornir_napalm/plugins/tasks/napalm_ping.py", line 37, in napalm_ping
    result = device.ping(
             ^^^^^^^^^^^^
  File "/Users/maiconlucinda/Documents/Python Code/Network Automation Python/nornir/.venv/lib/python3.11/site-packages/napalm/ios/ios.py", line 3387, in ping
    output = self._send_command(command)
             ^^^^^^^^^^^^^^^^^^^^^^^^^^^
  File "/Users/maiconlucinda/Documents/Python Code/Network Automation Python/nornir/.venv/lib/python3.11/site-packages/napalm/ios/ios.py", line 209, in _send_command
    output = self.device.send_command(command)
             ^^^^^^^^^^^^^^^^^^^^^^^^^^^^^^^^^
  File "/Users/maiconlucinda/Documents/Python Code/Network Automation Python/nornir/.venv/lib/python3.11/site-packages/netmiko/base_connection.py", line 111, in wrapper_decorator
    return_val = func(self, *args, **kwargs)
                 ^^^^^^^^^^^^^^^^^^^^^^^^^^^
  File "/Users/maiconlucinda/Documents/Python Code/Network Automation Python/nornir/.venv/lib/python3.11/site-packages/netmiko/utilities.py", line 596, in wrapper_decorator
    return func(self, *args, **kwargs)
           ^^^^^^^^^^^^^^^^^^^^^^^^^^^
  File "/Users/maiconlucinda/Documents/Python Code/Network Automation Python/nornir/.venv/lib/python3.11/site-packages/netmiko/base_connection.py", line 1826, in send_command
    raise ReadTimeout(msg)
netmiko.exceptions.ReadTimeout: 
Pattern not detected: 'R2\\#' in output.

Things you might try to fix this:
1. Explicitly set your pattern using the expect_string argument.
2. Increase the read_timeout to a larger value.

You can also look at the Netmiko session_log or debug log for more information.



2024-07-15 22:48:54,340 - nornir.core.task -    ERROR -      start() - Host 'R3': task 'ping_test' failed with traceback:
Traceback (most recent call last):
  File "/Users/maiconlucinda/Documents/Python Code/Network Automation Python/nornir/.venv/lib/python3.11/site-packages/nornir/core/task.py", line 99, in start
    r = self.task(self, **self.params)
        ^^^^^^^^^^^^^^^^^^^^^^^^^^^^^^
  File "/Users/maiconlucinda/Documents/Python Code/Network Automation Python/nornir/14_nornir_napalm_get_ping.py", line 10, in ping_test
    task.run(napalm_ping, dest="192.168.88.2")
  File "/Users/maiconlucinda/Documents/Python Code/Network Automation Python/nornir/.venv/lib/python3.11/site-packages/nornir/core/task.py", line 174, in run
    raise NornirSubTaskError(task=run_task, result=r)
nornir.core.exceptions.NornirSubTaskError: Subtask: napalm_ping (failed)


2024-07-15 22:48:54,340 - nornir.core.task -    ERROR -      start() - Host 'R1': task 'ping_test' failed with traceback:
Traceback (most recent call last):
  File "/Users/maiconlucinda/Documents/Python Code/Network Automation Python/nornir/.venv/lib/python3.11/site-packages/nornir/core/task.py", line 99, in start
    r = self.task(self, **self.params)
        ^^^^^^^^^^^^^^^^^^^^^^^^^^^^^^
  File "/Users/maiconlucinda/Documents/Python Code/Network Automation Python/nornir/14_nornir_napalm_get_ping.py", line 10, in ping_test
    task.run(napalm_ping, dest="192.168.88.2")
  File "/Users/maiconlucinda/Documents/Python Code/Network Automation Python/nornir/.venv/lib/python3.11/site-packages/nornir/core/task.py", line 174, in run
    raise NornirSubTaskError(task=run_task, result=r)
nornir.core.exceptions.NornirSubTaskError: Subtask: napalm_ping (failed)


2024-07-15 22:48:54,341 - nornir.core.task -    ERROR -      start() - Host 'R4': task 'ping_test' failed with traceback:
Traceback (most recent call last):
  File "/Users/maiconlucinda/Documents/Python Code/Network Automation Python/nornir/.venv/lib/python3.11/site-packages/nornir/core/task.py", line 99, in start
    r = self.task(self, **self.params)
        ^^^^^^^^^^^^^^^^^^^^^^^^^^^^^^
  File "/Users/maiconlucinda/Documents/Python Code/Network Automation Python/nornir/14_nornir_napalm_get_ping.py", line 10, in ping_test
    task.run(napalm_ping, dest="192.168.88.2")
  File "/Users/maiconlucinda/Documents/Python Code/Network Automation Python/nornir/.venv/lib/python3.11/site-packages/nornir/core/task.py", line 174, in run
    raise NornirSubTaskError(task=run_task, result=r)
nornir.core.exceptions.NornirSubTaskError: Subtask: napalm_ping (failed)


2024-07-15 22:48:54,341 - nornir.core.task -    ERROR -      start() - Host 'R2': task 'ping_test' failed with traceback:
Traceback (most recent call last):
  File "/Users/maiconlucinda/Documents/Python Code/Network Automation Python/nornir/.venv/lib/python3.11/site-packages/nornir/core/task.py", line 99, in start
    r = self.task(self, **self.params)
        ^^^^^^^^^^^^^^^^^^^^^^^^^^^^^^
  File "/Users/maiconlucinda/Documents/Python Code/Network Automation Python/nornir/14_nornir_napalm_get_ping.py", line 10, in ping_test
    task.run(napalm_ping, dest="192.168.88.2")
  File "/Users/maiconlucinda/Documents/Python Code/Network Automation Python/nornir/.venv/lib/python3.11/site-packages/nornir/core/task.py", line 174, in run
    raise NornirSubTaskError(task=run_task, result=r)
nornir.core.exceptions.NornirSubTaskError: Subtask: napalm_ping (failed)


2024-07-15 22:49:21,611 -  nornir.core -     INFO -        run() - Running task 'ping_test' with args {} on 4 hosts
2024-07-15 22:50:00,533 -  nornir.core -     INFO -        run() - Running task 'commit_flash' with args {} on 4 hosts
2024-07-15 22:50:33,110 - nornir.core.task -    ERROR -      start() - Host 'R3': task 'send_interactive' failed with traceback:
Traceback (most recent call last):
  File "/Users/maiconlucinda/Documents/Python Code/Network Automation Python/nornir/.venv/lib/python3.11/site-packages/nornir/core/task.py", line 99, in start
    r = self.task(self, **self.params)
        ^^^^^^^^^^^^^^^^^^^^^^^^^^^^^^
  File "/Users/maiconlucinda/Documents/Python Code/Network Automation Python/nornir/.venv/lib/python3.11/site-packages/nornir_scrapli/tasks/core/send_interactive.py", line 80, in send_interactive
    scrapli_response = scrapli_conn.send_interactive(
                       ^^^^^^^^^^^^^^^^^^^^^^^^^^^^^^
  File "/Users/maiconlucinda/Documents/Python Code/Network Automation Python/nornir/.venv/lib/python3.11/site-packages/scrapli/driver/network/sync_driver.py", line 460, in send_interactive
    response: Response = super().send_interactive(
                         ^^^^^^^^^^^^^^^^^^^^^^^^^
  File "/Users/maiconlucinda/Documents/Python Code/Network Automation Python/nornir/.venv/lib/python3.11/site-packages/scrapli/decorators.py", line 306, in decorate
    result = wrapped_func(*args, **kwargs)
             ^^^^^^^^^^^^^^^^^^^^^^^^^^^^^
  File "/Users/maiconlucinda/Documents/Python Code/Network Automation Python/nornir/.venv/lib/python3.11/site-packages/scrapli/driver/generic/sync_driver.py", line 462, in send_interactive
    raw_response, processed_response = self.channel.send_inputs_interact(
                                       ^^^^^^^^^^^^^^^^^^^^^^^^^^^^^^^^^^
  File "/Users/maiconlucinda/Documents/Python Code/Network Automation Python/nornir/.venv/lib/python3.11/site-packages/scrapli/decorators.py", line 223, in decorate
    return _multiprocessing_timeout(
           ^^^^^^^^^^^^^^^^^^^^^^^^^
  File "/Users/maiconlucinda/Documents/Python Code/Network Automation Python/nornir/.venv/lib/python3.11/site-packages/scrapli/decorators.py", line 109, in _multiprocessing_timeout
    return _handle_timeout(
           ^^^^^^^^^^^^^^^^
  File "/Users/maiconlucinda/Documents/Python Code/Network Automation Python/nornir/.venv/lib/python3.11/site-packages/scrapli/decorators.py", line 141, in _handle_timeout
    raise ScrapliTimeout(message)
scrapli.exceptions.ScrapliTimeout: timed out sending interactive input to device

2024-07-15 22:50:33,111 - nornir.core.task -    ERROR -      start() - Host 'R1': task 'send_interactive' failed with traceback:
Traceback (most recent call last):
  File "/Users/maiconlucinda/Documents/Python Code/Network Automation Python/nornir/.venv/lib/python3.11/site-packages/nornir/core/task.py", line 99, in start
    r = self.task(self, **self.params)
        ^^^^^^^^^^^^^^^^^^^^^^^^^^^^^^
  File "/Users/maiconlucinda/Documents/Python Code/Network Automation Python/nornir/.venv/lib/python3.11/site-packages/nornir_scrapli/tasks/core/send_interactive.py", line 80, in send_interactive
    scrapli_response = scrapli_conn.send_interactive(
                       ^^^^^^^^^^^^^^^^^^^^^^^^^^^^^^
  File "/Users/maiconlucinda/Documents/Python Code/Network Automation Python/nornir/.venv/lib/python3.11/site-packages/scrapli/driver/network/sync_driver.py", line 460, in send_interactive
    response: Response = super().send_interactive(
                         ^^^^^^^^^^^^^^^^^^^^^^^^^
  File "/Users/maiconlucinda/Documents/Python Code/Network Automation Python/nornir/.venv/lib/python3.11/site-packages/scrapli/decorators.py", line 306, in decorate
    result = wrapped_func(*args, **kwargs)
             ^^^^^^^^^^^^^^^^^^^^^^^^^^^^^
  File "/Users/maiconlucinda/Documents/Python Code/Network Automation Python/nornir/.venv/lib/python3.11/site-packages/scrapli/driver/generic/sync_driver.py", line 462, in send_interactive
    raw_response, processed_response = self.channel.send_inputs_interact(
                                       ^^^^^^^^^^^^^^^^^^^^^^^^^^^^^^^^^^
  File "/Users/maiconlucinda/Documents/Python Code/Network Automation Python/nornir/.venv/lib/python3.11/site-packages/scrapli/decorators.py", line 223, in decorate
    return _multiprocessing_timeout(
           ^^^^^^^^^^^^^^^^^^^^^^^^^
  File "/Users/maiconlucinda/Documents/Python Code/Network Automation Python/nornir/.venv/lib/python3.11/site-packages/scrapli/decorators.py", line 109, in _multiprocessing_timeout
    return _handle_timeout(
           ^^^^^^^^^^^^^^^^
  File "/Users/maiconlucinda/Documents/Python Code/Network Automation Python/nornir/.venv/lib/python3.11/site-packages/scrapli/decorators.py", line 141, in _handle_timeout
    raise ScrapliTimeout(message)
scrapli.exceptions.ScrapliTimeout: timed out sending interactive input to device

2024-07-15 22:50:33,119 - nornir.core.task -    ERROR -      start() - Host 'R3': task 'commit_flash' failed with traceback:
Traceback (most recent call last):
  File "/Users/maiconlucinda/Documents/Python Code/Network Automation Python/nornir/.venv/lib/python3.11/site-packages/nornir/core/task.py", line 99, in start
    r = self.task(self, **self.params)
        ^^^^^^^^^^^^^^^^^^^^^^^^^^^^^^
  File "/Users/maiconlucinda/Documents/Python Code/Network Automation Python/nornir/15_nornir_scarpli_interactive.py", line 10, in commit_flash
    task.run(task=send_interactive, interact_events=cmds)
  File "/Users/maiconlucinda/Documents/Python Code/Network Automation Python/nornir/.venv/lib/python3.11/site-packages/nornir/core/task.py", line 174, in run
    raise NornirSubTaskError(task=run_task, result=r)
nornir.core.exceptions.NornirSubTaskError: Subtask: send_interactive (failed)


2024-07-15 22:50:33,119 - nornir.core.task -    ERROR -      start() - Host 'R1': task 'commit_flash' failed with traceback:
Traceback (most recent call last):
  File "/Users/maiconlucinda/Documents/Python Code/Network Automation Python/nornir/.venv/lib/python3.11/site-packages/nornir/core/task.py", line 99, in start
    r = self.task(self, **self.params)
        ^^^^^^^^^^^^^^^^^^^^^^^^^^^^^^
  File "/Users/maiconlucinda/Documents/Python Code/Network Automation Python/nornir/15_nornir_scarpli_interactive.py", line 10, in commit_flash
    task.run(task=send_interactive, interact_events=cmds)
  File "/Users/maiconlucinda/Documents/Python Code/Network Automation Python/nornir/.venv/lib/python3.11/site-packages/nornir/core/task.py", line 174, in run
    raise NornirSubTaskError(task=run_task, result=r)
nornir.core.exceptions.NornirSubTaskError: Subtask: send_interactive (failed)


2024-07-15 22:50:33,120 - nornir.core.task -    ERROR -      start() - Host 'R2': task 'send_interactive' failed with traceback:
Traceback (most recent call last):
  File "/Users/maiconlucinda/Documents/Python Code/Network Automation Python/nornir/.venv/lib/python3.11/site-packages/nornir/core/task.py", line 99, in start
    r = self.task(self, **self.params)
        ^^^^^^^^^^^^^^^^^^^^^^^^^^^^^^
  File "/Users/maiconlucinda/Documents/Python Code/Network Automation Python/nornir/.venv/lib/python3.11/site-packages/nornir_scrapli/tasks/core/send_interactive.py", line 80, in send_interactive
    scrapli_response = scrapli_conn.send_interactive(
                       ^^^^^^^^^^^^^^^^^^^^^^^^^^^^^^
  File "/Users/maiconlucinda/Documents/Python Code/Network Automation Python/nornir/.venv/lib/python3.11/site-packages/scrapli/driver/network/sync_driver.py", line 460, in send_interactive
    response: Response = super().send_interactive(
                         ^^^^^^^^^^^^^^^^^^^^^^^^^
  File "/Users/maiconlucinda/Documents/Python Code/Network Automation Python/nornir/.venv/lib/python3.11/site-packages/scrapli/decorators.py", line 306, in decorate
    result = wrapped_func(*args, **kwargs)
             ^^^^^^^^^^^^^^^^^^^^^^^^^^^^^
  File "/Users/maiconlucinda/Documents/Python Code/Network Automation Python/nornir/.venv/lib/python3.11/site-packages/scrapli/driver/generic/sync_driver.py", line 462, in send_interactive
    raw_response, processed_response = self.channel.send_inputs_interact(
                                       ^^^^^^^^^^^^^^^^^^^^^^^^^^^^^^^^^^
  File "/Users/maiconlucinda/Documents/Python Code/Network Automation Python/nornir/.venv/lib/python3.11/site-packages/scrapli/decorators.py", line 223, in decorate
    return _multiprocessing_timeout(
           ^^^^^^^^^^^^^^^^^^^^^^^^^
  File "/Users/maiconlucinda/Documents/Python Code/Network Automation Python/nornir/.venv/lib/python3.11/site-packages/scrapli/decorators.py", line 109, in _multiprocessing_timeout
    return _handle_timeout(
           ^^^^^^^^^^^^^^^^
  File "/Users/maiconlucinda/Documents/Python Code/Network Automation Python/nornir/.venv/lib/python3.11/site-packages/scrapli/decorators.py", line 141, in _handle_timeout
    raise ScrapliTimeout(message)
scrapli.exceptions.ScrapliTimeout: timed out sending interactive input to device

2024-07-15 22:50:33,121 - nornir.core.task -    ERROR -      start() - Host 'R2': task 'commit_flash' failed with traceback:
Traceback (most recent call last):
  File "/Users/maiconlucinda/Documents/Python Code/Network Automation Python/nornir/.venv/lib/python3.11/site-packages/nornir/core/task.py", line 99, in start
    r = self.task(self, **self.params)
        ^^^^^^^^^^^^^^^^^^^^^^^^^^^^^^
  File "/Users/maiconlucinda/Documents/Python Code/Network Automation Python/nornir/15_nornir_scarpli_interactive.py", line 10, in commit_flash
    task.run(task=send_interactive, interact_events=cmds)
  File "/Users/maiconlucinda/Documents/Python Code/Network Automation Python/nornir/.venv/lib/python3.11/site-packages/nornir/core/task.py", line 174, in run
    raise NornirSubTaskError(task=run_task, result=r)
nornir.core.exceptions.NornirSubTaskError: Subtask: send_interactive (failed)


2024-07-15 22:50:33,123 - nornir.core.task -    ERROR -      start() - Host 'R4': task 'send_interactive' failed with traceback:
Traceback (most recent call last):
  File "/Users/maiconlucinda/Documents/Python Code/Network Automation Python/nornir/.venv/lib/python3.11/site-packages/nornir/core/task.py", line 99, in start
    r = self.task(self, **self.params)
        ^^^^^^^^^^^^^^^^^^^^^^^^^^^^^^
  File "/Users/maiconlucinda/Documents/Python Code/Network Automation Python/nornir/.venv/lib/python3.11/site-packages/nornir_scrapli/tasks/core/send_interactive.py", line 80, in send_interactive
    scrapli_response = scrapli_conn.send_interactive(
                       ^^^^^^^^^^^^^^^^^^^^^^^^^^^^^^
  File "/Users/maiconlucinda/Documents/Python Code/Network Automation Python/nornir/.venv/lib/python3.11/site-packages/scrapli/driver/network/sync_driver.py", line 460, in send_interactive
    response: Response = super().send_interactive(
                         ^^^^^^^^^^^^^^^^^^^^^^^^^
  File "/Users/maiconlucinda/Documents/Python Code/Network Automation Python/nornir/.venv/lib/python3.11/site-packages/scrapli/decorators.py", line 306, in decorate
    result = wrapped_func(*args, **kwargs)
             ^^^^^^^^^^^^^^^^^^^^^^^^^^^^^
  File "/Users/maiconlucinda/Documents/Python Code/Network Automation Python/nornir/.venv/lib/python3.11/site-packages/scrapli/driver/generic/sync_driver.py", line 462, in send_interactive
    raw_response, processed_response = self.channel.send_inputs_interact(
                                       ^^^^^^^^^^^^^^^^^^^^^^^^^^^^^^^^^^
  File "/Users/maiconlucinda/Documents/Python Code/Network Automation Python/nornir/.venv/lib/python3.11/site-packages/scrapli/decorators.py", line 223, in decorate
    return _multiprocessing_timeout(
           ^^^^^^^^^^^^^^^^^^^^^^^^^
  File "/Users/maiconlucinda/Documents/Python Code/Network Automation Python/nornir/.venv/lib/python3.11/site-packages/scrapli/decorators.py", line 109, in _multiprocessing_timeout
    return _handle_timeout(
           ^^^^^^^^^^^^^^^^
  File "/Users/maiconlucinda/Documents/Python Code/Network Automation Python/nornir/.venv/lib/python3.11/site-packages/scrapli/decorators.py", line 141, in _handle_timeout
    raise ScrapliTimeout(message)
scrapli.exceptions.ScrapliTimeout: timed out sending interactive input to device

2024-07-15 22:50:33,123 - nornir.core.task -    ERROR -      start() - Host 'R4': task 'commit_flash' failed with traceback:
Traceback (most recent call last):
  File "/Users/maiconlucinda/Documents/Python Code/Network Automation Python/nornir/.venv/lib/python3.11/site-packages/nornir/core/task.py", line 99, in start
    r = self.task(self, **self.params)
        ^^^^^^^^^^^^^^^^^^^^^^^^^^^^^^
  File "/Users/maiconlucinda/Documents/Python Code/Network Automation Python/nornir/15_nornir_scarpli_interactive.py", line 10, in commit_flash
    task.run(task=send_interactive, interact_events=cmds)
  File "/Users/maiconlucinda/Documents/Python Code/Network Automation Python/nornir/.venv/lib/python3.11/site-packages/nornir/core/task.py", line 174, in run
    raise NornirSubTaskError(task=run_task, result=r)
nornir.core.exceptions.NornirSubTaskError: Subtask: send_interactive (failed)


